Workbook
Name Slicer_Province_CLEAN: #N/A

Sheet bbw_canada_sales_raw
A1: TransactionID | B1: CustomerID | C1: Date | D1: Category | E1: Gender | F1: Age | G1: Location | H1: Quantity | I1: Sales | J1: Profit | K1: Channel | L1: Date_CLEAN | M1: Gender_CLEAN | N1: Age_CLEAN
A2: TXN-2024-000522 | B2: CUST-0058 | C2: 45618 | D2: Wallflower & Air Freshener | F2: 61 | G2: Lethbridge (AB) | H2: 1 | I2: 12.11 | J2: CAD 6.63 | K2: Online | L2: 45618 | M2: Unknown | N2: 61
A3: TXN-2023-000738 | B3: CUST-0312 | C3: 10/07/2023 | D3: Body Care | E3: N/A | G3: Vaughan Ontario | H3: 2 | I3: N/A | J3: 17.39 | K3: Online | L3: 45117 | M3: Unknown
A4: TXN-2024-000741 | B4: CUST-0309 | C4: 05/20/2024 | D4: Men's | E4: F | F4: 29 | G4: Toronto ON | H4: 1 | I4: 29,53 | J4: 13.19 | K4: Online | L4: 45432 | M4: Female | N4: 29
A5: TXN-2024-000661 | B5: CUST-0127 | C5: 04/10/2024 | D5: Wallflower & Air Freshener | E5: FEMALE | F5: 38 | G5: Kitchener Ontario | H5: 1 | I5: 7.33 | J5: CAD 2.94 | K5: Store | L5: 45569 | M5: Female | N5: 38
A6: TXN-2023-000412 | B6: CUST-0005 | C6: 14/06/2023 | D6: Wallflower & Air Freshener | E6: male | F6: 59 | G6: Vaughan (Ontario) | H6: 2 | I6: CAD 54.88 | J6: 20.71 | K6: Online | L6: 45091 | M6: Male | N6: 59
A7: TXN-2024-000679 | B7: CUST-0252 | C7: 45631 | D7: Candles | F7: 55 | G7: Calgary,Alberta | H7: 2 | I7: 106,03 | J7: 42,40 | K7: Store | L7: 45631 | M7: Unknown | N7: 55
A8: TXN-2023-000627 | B8: CUST-0235 | C8: 45144 | D8: Candles | E8: FEMALE | F8: 65 | G8: Gatineau, Quebec | H8: 2 | I8: 15.74 | J8: 7.12 | K8: Store | L8: 45144 | M8: Female | N8: 65
A9: TXN-2023-000514 | B9: CUST-0253 | C9: 45007 | D9: Men's | E9: M | F9: 56 | G9: Ottawa Ontari0 | H9: 4 | I9: 96,46 | J9: 24.26 | K9: Store | L9: 45007 | M9: Male | N9: 56
A10: TXN-2024-000860 | B10: CUST-0095 | C10: 45453 | D10: Wallflower & Air Freshener | E10: MALE | F10: 39 | G10: Mississauga, Ontario | H10: 1 | I10: 24.32 | J10: 8.65 | K10: Online | L10: 45453 | M10: Male | N10: 39
A11: TXN-2024-000137 | B11: CUST-0248 | C11: 21/07/2024 | D11: Wallflower & Air Freshener | E11: U | F11: 50 | G11: Alberta - Edmonton | H11: -4 | I11: -50.65 | J11: -16.77 | K11: Store | L11: 45494 | M11: Unknown | N11: 50
A12: Txn-2023-000812 | B12: CUST-0305 | C12: 2023.01.11 | D12: Body Care | E12: M | F12: twenty | G12: Saskatoon-SK | H12: 1 | I12: 23.1 | J12: 11,04 | K12: Store | L12: 44937 | M12: Male | N12: 20
A13: TXN-2024-000077 | B13: CUST-0070 | C13: 25/12/2024 | D13: Wallflower & Air Freshener | E13: M | F13: 14 | G13: Vancouver,British Columbia | H13: 2 | I13: 46.39 | J13: N/A | K13: Online | L13: 45651 | M13: Male | N13: 14
A14: TXN-2023-000637 | B14: CUST-0102 | C14: 02/07/2023 | D14: Men's | E14: female | F14: 69 | G14: Laval Quebec | H14: 1 | I14: CAD 16.21 | J14: 8.67 | K14: Store | L14: 45109 | M14: Female | N14: 69
A15: TXN-2023-000593 | B15: CUST-0211 | C15: 2023.04.21 | D15: Candles | E15: Female | F15: 60 | G15: Mississauga (Ontario) | H15: 1 | I15: 8.39 | J15: 2.65 | K15: Store | L15: 45037 | M15: Female | N15: 60
A16: TXN-2023-000939 | B16: CUST-0293 | C16: 11/18/2023 | D16: Wallflower & Air Freshener | E16: F | F16: 54 | G16: Laval Quebe | H16: 1 | I16: 8,28 | J16: 1.43 | K16: Online | L16: 45248 | M16: Female | N16: 54
A17: TXN-2023-000900 | B17: CUST-0086 | C17: 01/16/2023 | D17: Men's | E17: female | F17: 40 | G17: Ontario - Ottawa | H17: 1 | I17: 18.44 | J17: 7.13 | K17: Online | L17: 44942 | M17: Female | N17: 40
A18: TXN-2024-000281 | B18: CUST-0099 | C18: 2024.03.08 | D18: Men's | E18: FEMALE | F18: 65 | G18: Laval,Quebe | H18: 1 | I18: 16.02 | J18: 8.09 | K18: Store | L18: 45359 | M18: Female | N18: 65
A19: TXN-2024-000884 | B19: CUST-0012 | C19: 2024.05.29 | D19: Candles | E19: FEMALE | F19: 21 | G19: Laval Quebec | H19: 2 | I19: 54.5 | J19: 28.76 | K19: Store | L19: 45441 | M19: Female | N19: 21
A20: TXN-2023-000762 | B20: CUST-0051 | C20: 27/04/2023 | D20: Candles | E20: F | F20: 19 | G20: London,ONTARIO | H20: -2 | I20: -13.81 | J20: -19,81 | K20: Store | L20: 45043 | M20: Female | N20: 19
A21: TXN-2023-000320 | B21: CUST-0211 | C21: 45237 | D21: Men's | E21: female | F21: 66 | G21: Longueuil (Quebec) | H21: 3 | I21: 69.53 | J21: CAD 29.48 | K21: Store | L21: 45237 | M21: Female | N21: 66
A22: Txn-2024-000550 | B22: CUST-0170 | C22: 45421 | D22: Body Care | E22: Female | F22: 50 | G22: Red Deer-AB | H22: 1 | I22: 23.52 | J22: 12.51 | K22: Online | L22: 45421 | M22: Female | N22: 50
A23: TXN-2023-000175 | B23: CUST-0140 | C23: 44999 | D23: Body Care | E23: MALE | F23: 71 | G23: Kelowna BRITISH COLUMBIA | H23: 2 | I23: 20.26 | J23: 5.4 | K23: Online | L23: 44999 | M23: Male | N23: 71
A24: TXN-2024-000372 | B24: CUST-0053 | C24: 09/06/2024 | D24: Wallflower & Air Freshener | E24: M | F24: 18 | G24: Winnipeg (MANITOBA) | H24: 1 | I24: 4.92 | J24: 2.78 | K24: Store | L24: 45452 | M24: Male | N24: 18
A25: TXN-2024-000528 | B25: CUST-0061 | C25: 45410 | D25: Hand Soap & Sanitizer | E25: F | F25: 44 | G25: Markham,ON | H25: 2 | I25: 15.32 | J25: 6.15 | K25: Online | L25: 45410 | M25: Female | N25: 44
A26: Txn-2024-000211 | B26: CUST-0312 | C26: 45476 | D26: Men's | E26: Prefer not to say | F26: 47 | G26: Halifax (ns) | H26: 3 | I26: CAD 99.20 | J26: 31.93 | K26: Online | L26: 45476 | M26: Prefer not to say | N26: 47
A27: TXN-2024-000236 | B27: CUST-0034 | C27: 45607 | D27: Body Care | E27: MALE | F27: 74 | G27: Longueuil,Quebec | H27: 1 | I27: 15.43 CAD | J27: 7.69 | K27: Online | L27: 45607 | M27: Male | N27: 74
A28: TXN-2023-000102 | B28: CUST-0061 | C28: 4/7/2023 | D28: Candles | E28: Male | F28: 44 | G28: Calgary,Albert | H28: 1 | I28: 31.02 | J28: 11.15 | K28: Online | L28: 45111 | M28: Male | N28: 44
A29: TXN-2024-000652 | B29: CUST-0203 | C29: 25/11/2024 | D29: Wallflower & Air Freshener | E29: FEMALE | F29: 46 | G29: Longueuil,Quebe | H29: 3 | I29: 48.76 | J29: 27.2 | K29: Store | L29: 45621 | M29: Female | N29: 46
A30: TXN-2024-000903 | B30: CUST-0287 | C30: 45424 | D30: Candles | E30: MALE | F30: 43 | G30: Edmonton AB | H30: 4 | I30: 47.77 | J30: 29.42 | K30: Store | L30: 45424 | M30: Male | N30: 43
A31: TXN-2023-000948 | B31: CUST-0164 | C31: 44989 | D31: Wallflower & Air Freshener | E31: Male | F31: 48 | G31: Richmond,British Columbi | H31: 1 | I31: 13.96 CAD | J31: 4.71 | K31: Store | L31: 44989 | M31: Male | N31: 48
A32: TXN-2023-000347 | B32: CUST-0225 | C32: 45185 | D32: Candles | E32: F | F32: 44 | G32: Sherbrooke,Quebe | H32: 1 | I32: 44.26 | J32: 29.12 | K32: Online | L32: 45185 | M32: Female | N32: 44
A33: TXN-2024-000140 | B33: CUST-0071 | C33: 45489 | D33: Hand Soap & Sanitizer | E33: M | F33: 73 | G33: Windsor Ontario | H33: 1 | I33: 13.32 | J33: 4.92 | K33: Store | L33: 45489 | M33: Male | N33: 73
A34: TXN-2023-000622 | B34: CUST-0136 | C34: 03/07/2023 | D34: Candles | E34: N/A | F34: 31 | G34: Brampton / Ontari | H34: 1 | I34: 36,69 | J34: 20.08 | K34: Store | L34: 45110 | M34: Unknown | N34: 31
A35: TXN-2023-000500 | B35: CUST-0223 | C35: 44960 | D35: Men's | E35: FEMALE | F35: 34 | G35: Mississauga,ONTARIO | H35: 1 | I35: 18.94 | J35: 9.78 | K35: Online | L35: 44960 | M35: Female | N35: 34
A36: TXN-2023-000371 | B36: CUST-0279 | C36: 2023.12.25 | D36: Hand Soap & Sanitizer | E36: F | F36: 14 | G36: St. John's Newfoundland and Labrado | H36: 1 | I36: 8 | J36: 2.86 | K36: Online | L36: 45285 | M36: Female | N36: 14
A37: TXN-2024-000199 | B37: CUST-0110 | C37: 45647 | D37: Candles | E37: Male | F37: Thirty | G37: Laval-qc | H37: 3 | I37: 210.48 | K37: Online | L37: 45647 | M37: Male | N37: 30
A38: TXN-2023-000688 | B38: CUST-0155 | C38: 05/11/2023 | D38: Candles | E38: Female | F38: 38 | G38: on - Vaughan | H38: 3 | I38: 124.14 | J38: 47.04 | K38: Store | L38: 45235 | M38: Female | N38: 38
A39: TXN-2024-000585 | B39: CUST-0193 | C39: 2024.08.12 | D39: Hand Soap & Sanitizer | E39: FEMALE | F39: 26 | G39: Quebec - Longueuil | H39: 2 | I39: CAD 37.33 | J39: 8.86 | K39: Store | L39: 45516 | M39: Female | N39: 26
A40: TXN-2024-000902 | B40: CUST-0211 | C40: 02/07/2024 | D40: Wallflower & Air Freshener | E40: F | F40: 33 | G40: London-on | H40: 1 | I40: 4.84 | J40: 2.2 | K40: Online | L40: 45475 | M40: Female | N40: 33
...

Sheet bbw_canada_sales_SOLUTION
A1: TransactionID | B1: CustomerID | C1: Date | D1: Category | E1: Gender | F1: Age | G1: Location | H1: Quantity | I1: Sales | J1: Profit | K1: Channel | L1: Date_CLEAN | M1: Gender_CLEAN | N1: Age_CLEAN | O1: Age_GROUP | P1: Location | Q1: Province_CLEAN | R1: Sales_CLEAN | S1: Profit_CLEAN
A2: TXN-2024-000522 | B2: CUST-0058 | C2: 45618 | D2: Wallflower & Air Freshener | F2: 61 | G2: Lethbridge (AB) | H2: 1 | I2: 12.11 | J2: CAD 6.63 | K2: Online | L2: 45618 | M2: Unknown | N2: 61 | O2: {=IF(OR(Table1[[#This Row],[Age_CLEAN]]="",Table1[[#This Row],[Age_CLEAN]]=0), "Unknown", _xlfn.IFS( Table1[[#This Row],[Age_CLEAN]]<=17,"Teen (13-17)", Table1[[#This Row],[Age_CLEAN]]<=24,"Young Adult (18-24)", Table1[[#This Row],[Age_CLEAN]]<=34,"Adult (25-34)", Table1[[#This Row],[Age_CLEAN]]<=54,"Mid-Age (35-54)", Table1[[#This Row],[Age_CLEAN]]<=75,"Older Adult (55-75)", TRUE,"Out of Range" ))} -> Older Adult (55-75) | P2: Lethbridge (AB) | Q2: AB | R2: 12.11 | S2: 6.63
A3: TXN-2023-000738 | B3: CUST-0312 | C3: 10/07/2023 | D3: Body Care | E3: N/A | G3: Vaughan Ontario | H3: 2 | I3: N/A | J3: 17.39 | K3: Online | L3: 45117 | M3: Unknown | O3: {=IF(OR(Table1[[#This Row],[Age_CLEAN]]="",Table1[[#This Row],[Age_CLEAN]]=0), "Unknown", _xlfn.IFS( Table1[[#This Row],[Age_CLEAN]]<=17,"Teen (13-17)", Table1[[#This Row],[Age_CLEAN]]<=24,"Young Adult (18-24)", Table1[[#This Row],[Age_CLEAN]]<=34,"Adult (25-34)", Table1[[#This Row],[Age_CLEAN]]<=54,"Mid-Age (35-54)", Table1[[#This Row],[Age_CLEAN]]<=75,"Older Adult (55-75)", TRUE,"Out of Range" ))} -> Unknown | P3: Vaughan Ontario | Q3: ON | S3: 17.39
A4: TXN-2024-000741 | B4: CUST-0309 | C4: 05/20/2024 | D4: Men's | E4: F | F4: 29 | G4: Toronto ON | H4: 1 | I4: 29,53 | J4: 13.19 | K4: Online | L4: 45432 | M4: Female | N4: 29 | O4: {=IF(OR(Table1[[#This Row],[Age_CLEAN]]="",Table1[[#This Row],[Age_CLEAN]]=0), "Unknown", _xlfn.IFS( Table1[[#This Row],[Age_CLEAN]]<=17,"Teen (13-17)", Table1[[#This Row],[Age_CLEAN]]<=24,"Young Adult (18-24)", Table1[[#This Row],[Age_CLEAN]]<=34,"Adult (25-34)", Table1[[#This Row],[Age_CLEAN]]<=54,"Mid-Age (35-54)", Table1[[#This Row],[Age_CLEAN]]<=75,"Older Adult (55-75)", TRUE,"Out of Range" ))} -> Adult (25-34) | P4: Toronto ON | Q4: ON | R4: 29.53 | S4: 13.19
A5: TXN-2024-000661 | B5: CUST-0127 | C5: 04/10/2024 | D5: Wallflower & Air Freshener | E5: FEMALE | F5: 38 | G5: Kitchener Ontario | H5: 1 | I5: 7.33 | J5: CAD 2.94 | K5: Store | L5: 45569 | M5: Female | N5: 38 | O5: {=IF(OR(Table1[[#This Row],[Age_CLEAN]]="",Table1[[#This Row],[Age_CLEAN]]=0), "Unknown", _xlfn.IFS( Table1[[#This Row],[Age_CLEAN]]<=17,"Teen (13-17)", Table1[[#This Row],[Age_CLEAN]]<=24,"Young Adult (18-24)", Table1[[#This Row],[Age_CLEAN]]<=34,"Adult (25-34)", Table1[[#This Row],[Age_CLEAN]]<=54,"Mid-Age (35-54)", Table1[[#This Row],[Age_CLEAN]]<=75,"Older Adult (55-75)", TRUE,"Out of Range" ))} -> Mid-Age (35-54) | P5: Kitchener Ontario | Q5: ON | R5: 7.33 | S5: 2.94
A6: TXN-2023-000412 | B6: CUST-0005 | C6: 14/06/2023 | D6: Wallflower & Air Freshener | E6: male | F6: 59 | G6: Vaughan (Ontario) | H6: 2 | I6: CAD 54.88 | J6: 20.71 | K6: Online | L6: 45091 | M6: Male | N6: 59 | O6: {=IF(OR(Table1[[#This Row],[Age_CLEAN]]="",Table1[[#This Row],[Age_CLEAN]]=0), "Unknown", _xlfn.IFS( Table1[[#This Row],[Age_CLEAN]]<=17,"Teen (13-17)", Table1[[#This Row],[Age_CLEAN]]<=24,"Young Adult (18-24)", Table1[[#This Row],[Age_CLEAN]]<=34,"Adult (25-34)", Table1[[#This Row],[Age_CLEAN]]<=54,"Mid-Age (35-54)", Table1[[#This Row],[Age_CLEAN]]<=75,"Older Adult (55-75)", TRUE,"Out of Range" ))} -> Older Adult (55-75) | P6: Vaughan (Ontario) | Q6: ON | R6: 54.88 | S6: 20.71
A7: TXN-2024-000679 | B7: CUST-0252 | C7: 45631 | D7: Candles | F7: 55 | G7: Calgary,Alberta | H7: 2 | I7: 106,03 | J7: 42,40 | K7: Store | L7: 45631 | M7: Unknown | N7: 55 | O7: {=IF(OR(Table1[[#This Row],[Age_CLEAN]]="",Table1[[#This Row],[Age_CLEAN]]=0), "Unknown", _xlfn.IFS( Table1[[#This Row],[Age_CLEAN]]<=17,"Teen (13-17)", Table1[[#This Row],[Age_CLEAN]]<=24,"Young Adult (18-24)", Table1[[#This Row],[Age_CLEAN]]<=34,"Adult (25-34)", Table1[[#This Row],[Age_CLEAN]]<=54,"Mid-Age (35-54)", Table1[[#This Row],[Age_CLEAN]]<=75,"Older Adult (55-75)", TRUE,"Out of Range" ))} -> Older Adult (55-75) | P7: Calgary,Alberta | Q7: AB | R7: 106.03 | S7: 42.4
A8: TXN-2023-000627 | B8: CUST-0235 | C8: 45144 | D8: Candles | E8: FEMALE | F8: 65 | G8: Gatineau, Quebec | H8: 2 | I8: 15.74 | J8: 7.12 | K8: Store | L8: 45144 | M8: Female | N8: 65 | O8: {=IF(OR(Table1[[#This Row],[Age_CLEAN]]="",Table1[[#This Row],[Age_CLEAN]]=0), "Unknown", _xlfn.IFS( Table1[[#This Row],[Age_CLEAN]]<=17,"Teen (13-17)", Table1[[#This Row],[Age_CLEAN]]<=24,"Young Adult (18-24)", Table1[[#This Row],[Age_CLEAN]]<=34,"Adult (25-34)", Table1[[#This Row],[Age_CLEAN]]<=54,"Mid-Age (35-54)", Table1[[#This Row],[Age_CLEAN]]<=75,"Older Adult (55-75)", TRUE,"Out of Range" ))} -> Older Adult (55-75) | P8: Gatineau, Quebec | Q8: QC | R8: 15.74 | S8: 7.12
A9: TXN-2023-000514 | B9: CUST-0253 | C9: 45007 | D9: Men's | E9: M | F9: 56 | G9: Ottawa Ontari0 | H9: 4 | I9: 96,46 | J9: 24.26 | K9: Store | L9: 45007 | M9: Male | N9: 56 | O9: {=IF(OR(Table1[[#This Row],[Age_CLEAN]]="",Table1[[#This Row],[Age_CLEAN]]=0), "Unknown", _xlfn.IFS( Table1[[#This Row],[Age_CLEAN]]<=17,"Teen (13-17)", Table1[[#This Row],[Age_CLEAN]]<=24,"Young Adult (18-24)", Table1[[#This Row],[Age_CLEAN]]<=34,"Adult (25-34)", Table1[[#This Row],[Age_CLEAN]]<=54,"Mid-Age (35-54)", Table1[[#This Row],[Age_CLEAN]]<=75,"Older Adult (55-75)", TRUE,"Out of Range" ))} -> Older Adult (55-75) | P9: Ottawa Ontari0 | Q9: ON | R9: 96.46 | S9: 24.26
A10: TXN-2024-000860 | B10: CUST-0095 | C10: 45453 | D10: Wallflower & Air Freshener | E10: MALE | F10: 39 | G10: Mississauga, Ontario | H10: 1 | I10: 24.32 | J10: 8.65 | K10: Online | L10: 45453 | M10: Male | N10: 39 | O10: {=IF(OR(Table1[[#This Row],[Age_CLEAN]]="",Table1[[#This Row],[Age_CLEAN]]=0), "Unknown", _xlfn.IFS( Table1[[#This Row],[Age_CLEAN]]<=17,"Teen (13-17)", Table1[[#This Row],[Age_CLEAN]]<=24,"Young Adult (18-24)", Table1[[#This Row],[Age_CLEAN]]<=34,"Adult (25-34)", Table1[[#This Row],[Age_CLEAN]]<=54,"Mid-Age (35-54)", Table1[[#This Row],[Age_CLEAN]]<=75,"Older Adult (55-75)", TRUE,"Out of Range" ))} -> Mid-Age (35-54) | P10: Mississauga, Ontario | Q10: ON | R10: 24.32 | S10: 8.65
A11: TXN-2024-000137 | B11: CUST-0248 | C11: 21/07/2024 | D11: Wallflower & Air Freshener | E11: U | F11: 50 | G11: Alberta - Edmonton | H11: -4 | I11: -50.65 | J11: -16.77 | K11: Store | L11: 45494 | M11: Unknown | N11: 50 | O11: {=IF(OR(Table1[[#This Row],[Age_CLEAN]]="",Table1[[#This Row],[Age_CLEAN]]=0), "Unknown", _xlfn.IFS( Table1[[#This Row],[Age_CLEAN]]<=17,"Teen (13-17)", Table1[[#This Row],[Age_CLEAN]]<=24,"Young Adult (18-24)", Table1[[#This Row],[Age_CLEAN]]<=34,"Adult (25-34)", Table1[[#This Row],[Age_CLEAN]]<=54,"Mid-Age (35-54)", Table1[[#This Row],[Age_CLEAN]]<=75,"Older Adult (55-75)", TRUE,"Out of Range" ))} -> Mid-Age (35-54) | P11: Alberta - Edmonton | Q11: AB | R11: -50.65 | S11: -16.77
A12: Txn-2023-000812 | B12: CUST-0305 | C12: 2023.01.11 | D12: Body Care | E12: M | F12: twenty | G12: Saskatoon-SK | H12: 1 | I12: 23.1 | J12: 11,04 | K12: Store | L12: 44937 | M12: Male | N12: 20 | O12: {=IF(OR(Table1[[#This Row],[Age_CLEAN]]="",Table1[[#This Row],[Age_CLEAN]]=0), "Unknown", _xlfn.IFS( Table1[[#This Row],[Age_CLEAN]]<=17,"Teen (13-17)", Table1[[#This Row],[Age_CLEAN]]<=24,"Young Adult (18-24)", Table1[[#This Row],[Age_CLEAN]]<=34,"Adult (25-34)", Table1[[#This Row],[Age_CLEAN]]<=54,"Mid-Age (35-54)", Table1[[#This Row],[Age_CLEAN]]<=75,"Older Adult (55-75)", TRUE,"Out of Range" ))} -> Young Adult (18-24) | P12: Saskatoon-SK | Q12: SK | R12: 23.1 | S12: 11.04
A13: TXN-2024-000077 | B13: CUST-0070 | C13: 25/12/2024 | D13: Wallflower & Air Freshener | E13: M | F13: 14 | G13: Vancouver,British Columbia | H13: 2 | I13: 46.39 | J13: N/A | K13: Online | L13: 45651 | M13: Male | N13: 14 | O13: {=IF(OR(Table1[[#This Row],[Age_CLEAN]]="",Table1[[#This Row],[Age_CLEAN]]=0), "Unknown", _xlfn.IFS( Table1[[#This Row],[Age_CLEAN]]<=17,"Teen (13-17)", Table1[[#This Row],[Age_CLEAN]]<=24,"Young Adult (18-24)", Table1[[#This Row],[Age_CLEAN]]<=34,"Adult (25-34)", Table1[[#This Row],[Age_CLEAN]]<=54,"Mid-Age (35-54)", Table1[[#This Row],[Age_CLEAN]]<=75,"Older Adult (55-75)", TRUE,"Out of Range" ))} -> Teen (13-17) | P13: Vancouver,British Columbia | Q13: BC | R13: 46.39
A14: TXN-2023-000637 | B14: CUST-0102 | C14: 02/07/2023 | D14: Men's | E14: female | F14: 69 | G14: Laval Quebec | H14: 1 | I14: CAD 16.21 | J14: 8.67 | K14: Store | L14: 45109 | M14: Female | N14: 69 | O14: {=IF(OR(Table1[[#This Row],[Age_CLEAN]]="",Table1[[#This Row],[Age_CLEAN]]=0), "Unknown", _xlfn.IFS( Table1[[#This Row],[Age_CLEAN]]<=17,"Teen (13-17)", Table1[[#This Row],[Age_CLEAN]]<=24,"Young Adult (18-24)", Table1[[#This Row],[Age_CLEAN]]<=34,"Adult (25-34)", Table1[[#This Row],[Age_CLEAN]]<=54,"Mid-Age (35-54)", Table1[[#This Row],[Age_CLEAN]]<=75,"Older Adult (55-75)", TRUE,"Out of Range" ))} -> Older Adult (55-75) | P14: Laval Quebec | Q14: QC | R14: 16.21 | S14: 8.67
A15: TXN-2023-000593 | B15: CUST-0211 | C15: 2023.04.21 | D15: Candles | E15: Female | F15: 60 | G15: Mississauga (Ontario) | H15: 1 | I15: 8.39 | J15: 2.65 | K15: Store | L15: 45037 | M15: Female | N15: 60 | O15: {=IF(OR(Table1[[#This Row],[Age_CLEAN]]="",Table1[[#This Row],[Age_CLEAN]]=0), "Unknown", _xlfn.IFS( Table1[[#This Row],[Age_CLEAN]]<=17,"Teen (13-17)", Table1[[#This Row],[Age_CLEAN]]<=24,"Young Adult (18-24)", Table1[[#This Row],[Age_CLEAN]]<=34,"Adult (25-34)", Table1[[#This Row],[Age_CLEAN]]<=54,"Mid-Age (35-54)", Table1[[#This Row],[Age_CLEAN]]<=75,"Older Adult (55-75)", TRUE,"Out of Range" ))} -> Older Adult (55-75) | P15: Mississauga (Ontario) | Q15: ON | R15: 8.39 | S15: 2.65
A16: TXN-2023-000939 | B16: CUST-0293 | C16: 11/18/2023 | D16: Wallflower & Air Freshener | E16: F | F16: 54 | G16: Laval Quebe | H16: 1 | I16: 8,28 | J16: 1.43 | K16: Online | L16: 45248 | M16: Female | N16: 54 | O16: {=IF(OR(Table1[[#This Row],[Age_CLEAN]]="",Table1[[#This Row],[Age_CLEAN]]=0), "Unknown", _xlfn.IFS( Table1[[#This Row],[Age_CLEAN]]<=17,"Teen (13-17)", Table1[[#This Row],[Age_CLEAN]]<=24,"Young Adult (18-24)", Table1[[#This Row],[Age_CLEAN]]<=34,"Adult (25-34)", Table1[[#This Row],[Age_CLEAN]]<=54,"Mid-Age (35-54)", Table1[[#This Row],[Age_CLEAN]]<=75,"Older Adult (55-75)", TRUE,"Out of Range" ))} -> Mid-Age (35-54) | P16: Laval Quebe | Q16: QC | R16: 8.28 | S16: 1.43
A17: TXN-2023-000900 | B17: CUST-0086 | C17: 01/16/2023 | D17: Men's | E17: female | F17: 40 | G17: Ontario - Ottawa | H17: 1 | I17: 18.44 | J17: 7.13 | K17: Online | L17: 44942 | M17: Female | N17: 40 | O17: {=IF(OR(Table1[[#This Row],[Age_CLEAN]]="",Table1[[#This Row],[Age_CLEAN]]=0), "Unknown", _xlfn.IFS( Table1[[#This Row],[Age_CLEAN]]<=17,"Teen (13-17)", Table1[[#This Row],[Age_CLEAN]]<=24,"Young Adult (18-24)", Table1[[#This Row],[Age_CLEAN]]<=34,"Adult (25-34)", Table1[[#This Row],[Age_CLEAN]]<=54,"Mid-Age (35-54)", Table1[[#This Row],[Age_CLEAN]]<=75,"Older Adult (55-75)", TRUE,"Out of Range" ))} -> Mid-Age (35-54) | P17: Ontario - Ottawa | Q17: ON | R17: 18.44 | S17: 7.13
A18: TXN-2024-000281 | B18: CUST-0099 | C18: 2024.03.08 | D18: Men's | E18: FEMALE | F18: 65 | G18: Laval,Quebe | H18: 1 | I18: 16.02 | J18: 8.09 | K18: Store | L18: 45359 | M18: Female | N18: 65 | O18: {=IF(OR(Table1[[#This Row],[Age_CLEAN]]="",Table1[[#This Row],[Age_CLEAN]]=0), "Unknown", _xlfn.IFS( Table1[[#This Row],[Age_CLEAN]]<=17,"Teen (13-17)", Table1[[#This Row],[Age_CLEAN]]<=24,"Young Adult (18-24)", Table1[[#This Row],[Age_CLEAN]]<=34,"Adult (25-34)", Table1[[#This Row],[Age_CLEAN]]<=54,"Mid-Age (35-54)", Table1[[#This Row],[Age_CLEAN]]<=75,"Older Adult (55-75)", TRUE,"Out of Range" ))} -> Older Adult (55-75) | P18: Laval,Quebe | Q18: QC | R18: 16.02 | S18: 8.09
A19: TXN-2024-000884 | B19: CUST-0012 | C19: 2024.05.29 | D19: Candles | E19: FEMALE | F19: 21 | G19: Laval Quebec | H19: 2 | I19: 54.5 | J19: 28.76 | K19: Store | L19: 45441 | M19: Female | N19: 21 | O19: {=IF(OR(Table1[[#This Row],[Age_CLEAN]]="",Table1[[#This Row],[Age_CLEAN]]=0), "Unknown", _xlfn.IFS( Table1[[#This Row],[Age_CLEAN]]<=17,"Teen (13-17)", Table1[[#This Row],[Age_CLEAN]]<=24,"Young Adult (18-24)", Table1[[#This Row],[Age_CLEAN]]<=34,"Adult (25-34)", Table1[[#This Row],[Age_CLEAN]]<=54,"Mid-Age (35-54)", Table1[[#This Row],[Age_CLEAN]]<=75,"Older Adult (55-75)", TRUE,"Out of Range" ))} -> Young Adult (18-24) | P19: Laval Quebec | Q19: QC | R19: 54.5 | S19: 28.76
A20: TXN-2023-000762 | B20: CUST-0051 | C20: 27/04/2023 | D20: Candles | E20: F | F20: 19 | G20: London,ONTARIO | H20: -2 | I20: -13.81 | J20: -19,81 | K20: Store | L20: 45043 | M20: Female | N20: 19 | O20: {=IF(OR(Table1[[#This Row],[Age_CLEAN]]="",Table1[[#This Row],[Age_CLEAN]]=0), "Unknown", _xlfn.IFS( Table1[[#This Row],[Age_CLEAN]]<=17,"Teen (13-17)", Table1[[#This Row],[Age_CLEAN]]<=24,"Young Adult (18-24)", Table1[[#This Row],[Age_CLEAN]]<=34,"Adult (25-34)", Table1[[#This Row],[Age_CLEAN]]<=54,"Mid-Age (35-54)", Table1[[#This Row],[Age_CLEAN]]<=75,"Older Adult (55-75)", TRUE,"Out of Range" ))} -> Young Adult (18-24) | P20: London,ONTARIO | Q20: ON | R20: -13.81 | S20: -19.81
A21: TXN-2023-000320 | B21: CUST-0211 | C21: 45237 | D21: Men's | E21: female | F21: 66 | G21: Longueuil (Quebec) | H21: 3 | I21: 69.53 | J21: CAD 29.48 | K21: Store | L21: 45237 | M21: Female | N21: 66 | O21: {=IF(OR(Table1[[#This Row],[Age_CLEAN]]="",Table1[[#This Row],[Age_CLEAN]]=0), "Unknown", _xlfn.IFS( Table1[[#This Row],[Age_CLEAN]]<=17,"Teen (13-17)", Table1[[#This Row],[Age_CLEAN]]<=24,"Young Adult (18-24)", Table1[[#This Row],[Age_CLEAN]]<=34,"Adult (25-34)", Table1[[#This Row],[Age_CLEAN]]<=54,"Mid-Age (35-54)", Table1[[#This Row],[Age_CLEAN]]<=75,"Older Adult (55-75)", TRUE,"Out of Range" ))} -> Older Adult (55-75) | P21: Longueuil (Quebec) | Q21: QC | R21: 69.53 | S21: 29.48
A22: Txn-2024-000550 | B22: CUST-0170 | C22: 45421 | D22: Body Care | E22: Female | F22: 50 | G22: Red Deer-AB | H22: 1 | I22: 23.52 | J22: 12.51 | K22: Online | L22: 45421 | M22: Female | N22: 50 | O22: {=IF(OR(Table1[[#This Row],[Age_CLEAN]]="",Table1[[#This Row],[Age_CLEAN]]=0), "Unknown", _xlfn.IFS( Table1[[#This Row],[Age_CLEAN]]<=17,"Teen (13-17)", Table1[[#This Row],[Age_CLEAN]]<=24,"Young Adult (18-24)", Table1[[#This Row],[Age_CLEAN]]<=34,"Adult (25-34)", Table1[[#This Row],[Age_CLEAN]]<=54,"Mid-Age (35-54)", Table1[[#This Row],[Age_CLEAN]]<=75,"Older Adult (55-75)", TRUE,"Out of Range" ))} -> Mid-Age (35-54) | P22: Red Deer-AB | Q22: AB | R22: 23.52 | S22: 12.51
A23: TXN-2023-000175 | B23: CUST-0140 | C23: 44999 | D23: Body Care | E23: MALE | F23: 71 | G23: Kelowna BRITISH COLUMBIA | H23: 2 | I23: 20.26 | J23: 5.4 | K23: Online | L23: 44999 | M23: Male | N23: 71 | O23: {=IF(OR(Table1[[#This Row],[Age_CLEAN]]="",Table1[[#This Row],[Age_CLEAN]]=0), "Unknown", _xlfn.IFS( Table1[[#This Row],[Age_CLEAN]]<=17,"Teen (13-17)", Table1[[#This Row],[Age_CLEAN]]<=24,"Young Adult (18-24)", Table1[[#This Row],[Age_CLEAN]]<=34,"Adult (25-34)", Table1[[#This Row],[Age_CLEAN]]<=54,"Mid-Age (35-54)", Table1[[#This Row],[Age_CLEAN]]<=75,"Older Adult (55-75)", TRUE,"Out of Range" ))} -> Older Adult (55-75) | P23: Kelowna BRITISH COLUMBIA | Q23: BC | R23: 20.26 | S23: 5.4
A24: TXN-2024-000372 | B24: CUST-0053 | C24: 09/06/2024 | D24: Wallflower & Air Freshener | E24: M | F24: 18 | G24: Winnipeg (MANITOBA) | H24: 1 | I24: 4.92 | J24: 2.78 | K24: Store | L24: 45452 | M24: Male | N24: 18 | O24: {=IF(OR(Table1[[#This Row],[Age_CLEAN]]="",Table1[[#This Row],[Age_CLEAN]]=0), "Unknown", _xlfn.IFS( Table1[[#This Row],[Age_CLEAN]]<=17,"Teen (13-17)", Table1[[#This Row],[Age_CLEAN]]<=24,"Young Adult (18-24)", Table1[[#This Row],[Age_CLEAN]]<=34,"Adult (25-34)", Table1[[#This Row],[Age_CLEAN]]<=54,"Mid-Age (35-54)", Table1[[#This Row],[Age_CLEAN]]<=75,"Older Adult (55-75)", TRUE,"Out of Range" ))} -> Young Adult (18-24) | P24: Winnipeg (MANITOBA) | Q24: MB | R24: 4.92 | S24: 2.78
A25: TXN-2024-000528 | B25: CUST-0061 | C25: 45410 | D25: Hand Soap & Sanitizer | E25: F | F25: 44 | G25: Markham,ON | H25: 2 | I25: 15.32 | J25: 6.15 | K25: Online | L25: 45410 | M25: Female | N25: 44 | O25: {=IF(OR(Table1[[#This Row],[Age_CLEAN]]="",Table1[[#This Row],[Age_CLEAN]]=0), "Unknown", _xlfn.IFS( Table1[[#This Row],[Age_CLEAN]]<=17,"Teen (13-17)", Table1[[#This Row],[Age_CLEAN]]<=24,"Young Adult (18-24)", Table1[[#This Row],[Age_CLEAN]]<=34,"Adult (25-34)", Table1[[#This Row],[Age_CLEAN]]<=54,"Mid-Age (35-54)", Table1[[#This Row],[Age_CLEAN]]<=75,"Older Adult (55-75)", TRUE,"Out of Range" ))} -> Mid-Age (35-54) | P25: Markham,ON | Q25: ON | R25: 15.32 | S25: 6.15
A26: Txn-2024-000211 | B26: CUST-0312 | C26: 45476 | D26: Men's | E26: Prefer not to say | F26: 47 | G26: Halifax (ns) | H26: 3 | I26: CAD 99.20 | J26: 31.93 | K26: Online | L26: 45476 | M26: Prefer not to say | N26: 47 | O26: {=IF(OR(Table1[[#This Row],[Age_CLEAN]]="",Table1[[#This Row],[Age_CLEAN]]=0), "Unknown", _xlfn.IFS( Table1[[#This Row],[Age_CLEAN]]<=17,"Teen (13-17)", Table1[[#This Row],[Age_CLEAN]]<=24,"Young Adult (18-24)", Table1[[#This Row],[Age_CLEAN]]<=34,"Adult (25-34)", Table1[[#This Row],[Age_CLEAN]]<=54,"Mid-Age (35-54)", Table1[[#This Row],[Age_CLEAN]]<=75,"Older Adult (55-75)", TRUE,"Out of Range" ))} -> Mid-Age (35-54) | P26: Halifax (ns) | Q26: NS | R26: 99.2 | S26: 31.93
A27: TXN-2024-000236 | B27: CUST-0034 | C27: 45607 | D27: Body Care | E27: MALE | F27: 74 | G27: Longueuil,Quebec | H27: 1 | I27: 15.43 CAD | J27: 7.69 | K27: Online | L27: 45607 | M27: Male | N27: 74 | O27: {=IF(OR(Table1[[#This Row],[Age_CLEAN]]="",Table1[[#This Row],[Age_CLEAN]]=0), "Unknown", _xlfn.IFS( Table1[[#This Row],[Age_CLEAN]]<=17,"Teen (13-17)", Table1[[#This Row],[Age_CLEAN]]<=24,"Young Adult (18-24)", Table1[[#This Row],[Age_CLEAN]]<=34,"Adult (25-34)", Table1[[#This Row],[Age_CLEAN]]<=54,"Mid-Age (35-54)", Table1[[#This Row],[Age_CLEAN]]<=75,"Older Adult (55-75)", TRUE,"Out of Range" ))} -> Older Adult (55-75) | P27: Longueuil,Quebec | Q27: QC | R27: 15.43 | S27: 7.69
A28: TXN-2023-000102 | B28: CUST-0061 | C28: 4/7/2023 | D28: Candles | E28: Male | F28: 44 | G28: Calgary,Albert | H28: 1 | I28: 31.02 | J28: 11.15 | K28: Online | L28: 45111 | M28: Male | N28: 44 | O28: {=IF(OR(Table1[[#This Row],[Age_CLEAN]]="",Table1[[#This Row],[Age_CLEAN]]=0), "Unknown", _xlfn.IFS( Table1[[#This Row],[Age_CLEAN]]<=17,"Teen (13-17)", Table1[[#This Row],[Age_CLEAN]]<=24,"Young Adult (18-24)", Table1[[#This Row],[Age_CLEAN]]<=34,"Adult (25-34)", Table1[[#This Row],[Age_CLEAN]]<=54,"Mid-Age (35-54)", Table1[[#This Row],[Age_CLEAN]]<=75,"Older Adult (55-75)", TRUE,"Out of Range" ))} -> Mid-Age (35-54) | P28: Calgary,Albert | Q28: AB | R28: 31.02 | S28: 11.15
A29: TXN-2024-000652 | B29: CUST-0203 | C29: 25/11/2024 | D29: Wallflower & Air Freshener | E29: FEMALE | F29: 46 | G29: Longueuil,Quebe | H29: 3 | I29: 48.76 | J29: 27.2 | K29: Store | L29: 45621 | M29: Female | N29: 46 | O29: {=IF(OR(Table1[[#This Row],[Age_CLEAN]]="",Table1[[#This Row],[Age_CLEAN]]=0), "Unknown", _xlfn.IFS( Table1[[#This Row],[Age_CLEAN]]<=17,"Teen (13-17)", Table1[[#This Row],[Age_CLEAN]]<=24,"Young Adult (18-24)", Table1[[#This Row],[Age_CLEAN]]<=34,"Adult (25-34)", Table1[[#This Row],[Age_CLEAN]]<=54,"Mid-Age (35-54)", Table1[[#This Row],[Age_CLEAN]]<=75,"Older Adult (55-75)", TRUE,"Out of Range" ))} -> Mid-Age (35-54) | P29: Longueuil,Quebe | Q29: QC | R29: 48.76 | S29: 27.2
A30: TXN-2024-000903 | B30: CUST-0287 | C30: 45424 | D30: Candles | E30: MALE | F30: 43 | G30: Edmonton AB | H30: 4 | I30: 47.77 | J30: 29.42 | K30: Store | L30: 45424 | M30: Male | N30: 43 | O30: {=IF(OR(Table1[[#This Row],[Age_CLEAN]]="",Table1[[#This Row],[Age_CLEAN]]=0), "Unknown", _xlfn.IFS( Table1[[#This Row],[Age_CLEAN]]<=17,"Teen (13-17)", Table1[[#This Row],[Age_CLEAN]]<=24,"Young Adult (18-24)", Table1[[#This Row],[Age_CLEAN]]<=34,"Adult (25-34)", Table1[[#This Row],[Age_CLEAN]]<=54,"Mid-Age (35-54)", Table1[[#This Row],[Age_CLEAN]]<=75,"Older Adult (55-75)", TRUE,"Out of Range" ))} -> Mid-Age (35-54) | P30: Edmonton AB | Q30: AB | R30: 47.77 | S30: 29.42
A31: TXN-2023-000948 | B31: CUST-0164 | C31: 44989 | D31: Wallflower & Air Freshener | E31: Male | F31: 48 | G31: Richmond,British Columbi | H31: 1 | I31: 13.96 CAD | J31: 4.71 | K31: Store | L31: 44989 | M31: Male | N31: 48 | O31: {=IF(OR(Table1[[#This Row],[Age_CLEAN]]="",Table1[[#This Row],[Age_CLEAN]]=0), "Unknown", _xlfn.IFS( Table1[[#This Row],[Age_CLEAN]]<=17,"Teen (13-17)", Table1[[#This Row],[Age_CLEAN]]<=24,"Young Adult (18-24)", Table1[[#This Row],[Age_CLEAN]]<=34,"Adult (25-34)", Table1[[#This Row],[Age_CLEAN]]<=54,"Mid-Age (35-54)", Table1[[#This Row],[Age_CLEAN]]<=75,"Older Adult (55-75)", TRUE,"Out of Range" ))} -> Mid-Age (35-54) | P31: Richmond,British Columbi | Q31: BC | R31: 13.96 | S31: 4.71
A32: TXN-2023-000347 | B32: CUST-0225 | C32: 45185 | D32: Candles | E32: F | F32: 44 | G32: Sherbrooke,Quebe | H32: 1 | I32: 44.26 | J32: 29.12 | K32: Online | L32: 45185 | M32: Female | N32: 44 | O32: {=IF(OR(Table1[[#This Row],[Age_CLEAN]]="",Table1[[#This Row],[Age_CLEAN]]=0), "Unknown", _xlfn.IFS( Table1[[#This Row],[Age_CLEAN]]<=17,"Teen (13-17)", Table1[[#This Row],[Age_CLEAN]]<=24,"Young Adult (18-24)", Table1[[#This Row],[Age_CLEAN]]<=34,"Adult (25-34)", Table1[[#This Row],[Age_CLEAN]]<=54,"Mid-Age (35-54)", Table1[[#This Row],[Age_CLEAN]]<=75,"Older Adult (55-75)", TRUE,"Out of Range" ))} -> Mid-Age (35-54) | P32: Sherbrooke,Quebe | Q32: QC | R32: 44.26 | S32: 29.12
A33: TXN-2024-000140 | B33: CUST-0071 | C33: 45489 | D33: Hand Soap & Sanitizer | E33: M | F33: 73 | G33: Windsor Ontario | H33: 1 | I33: 13.32 | J33: 4.92 | K33: Store | L33: 45489 | M33: Male | N33: 73 | O33: {=IF(OR(Table1[[#This Row],[Age_CLEAN]]="",Table1[[#This Row],[Age_CLEAN]]=0), "Unknown", _xlfn.IFS( Table1[[#This Row],[Age_CLEAN]]<=17,"Teen (13-17)", Table1[[#This Row],[Age_CLEAN]]<=24,"Young Adult (18-24)", Table1[[#This Row],[Age_CLEAN]]<=34,"Adult (25-34)", Table1[[#This Row],[Age_CLEAN]]<=54,"Mid-Age (35-54)", Table1[[#This Row],[Age_CLEAN]]<=75,"Older Adult (55-75)", TRUE,"Out of Range" ))} -> Older Adult (55-75) | P33: Windsor Ontario | Q33: ON | R33: 13.32 | S33: 4.92
A34: TXN-2023-000622 | B34: CUST-0136 | C34: 03/07/2023 | D34: Candles | E34: N/A | F34: 31 | G34: Brampton / Ontari | H34: 1 | I34: 36,69 | J34: 20.08 | K34: Store | L34: 45110 | M34: Unknown | N34: 31 | O34: {=IF(OR(Table1[[#This Row],[Age_CLEAN]]="",Table1[[#This Row],[Age_CLEAN]]=0), "Unknown", _xlfn.IFS( Table1[[#This Row],[Age_CLEAN]]<=17,"Teen (13-17)", Table1[[#This Row],[Age_CLEAN]]<=24,"Young Adult (18-24)", Table1[[#This Row],[Age_CLEAN]]<=34,"Adult (25-34)", Table1[[#This Row],[Age_CLEAN]]<=54,"Mid-Age (35-54)", Table1[[#This Row],[Age_CLEAN]]<=75,"Older Adult (55-75)", TRUE,"Out of Range" ))} -> Adult (25-34) | P34: Brampton / Ontari | Q34: ON | R34: 36.69 | S34: 20.08
A35: TXN-2023-000500 | B35: CUST-0223 | C35: 44960 | D35: Men's | E35: FEMALE | F35: 34 | G35: Mississauga,ONTARIO | H35: 1 | I35: 18.94 | J35: 9.78 | K35: Online | L35: 44960 | M35: Female | N35: 34 | O35: {=IF(OR(Table1[[#This Row],[Age_CLEAN]]="",Table1[[#This Row],[Age_CLEAN]]=0), "Unknown", _xlfn.IFS( Table1[[#This Row],[Age_CLEAN]]<=17,"Teen (13-17)", Table1[[#This Row],[Age_CLEAN]]<=24,"Young Adult (18-24)", Table1[[#This Row],[Age_CLEAN]]<=34,"Adult (25-34)", Table1[[#This Row],[Age_CLEAN]]<=54,"Mid-Age (35-54)", Table1[[#This Row],[Age_CLEAN]]<=75,"Older Adult (55-75)", TRUE,"Out of Range" ))} -> Adult (25-34) | P35: Mississauga,ONTARIO | Q35: ON | R35: 18.94 | S35: 9.78
A36: TXN-2023-000371 | B36: CUST-0279 | C36: 2023.12.25 | D36: Hand Soap & Sanitizer | E36: F | F36: 14 | G36: St. John's Newfoundland and Labrado | H36: 1 | I36: 8 | J36: 2.86 | K36: Online | L36: 45285 | M36: Female | N36: 14 | O36: {=IF(OR(Table1[[#This Row],[Age_CLEAN]]="",Table1[[#This Row],[Age_CLEAN]]=0), "Unknown", _xlfn.IFS( Table1[[#This Row],[Age_CLEAN]]<=17,"Teen (13-17)", Table1[[#This Row],[Age_CLEAN]]<=24,"Young Adult (18-24)", Table1[[#This Row],[Age_CLEAN]]<=34,"Adult (25-34)", Table1[[#This Row],[Age_CLEAN]]<=54,"Mid-Age (35-54)", Table1[[#This Row],[Age_CLEAN]]<=75,"Older Adult (55-75)", TRUE,"Out of Range" ))} -> Teen (13-17) | P36: St. John's Newfoundland and Labrado | Q36: NL | R36: 8 | S36: 2.86
A37: TXN-2024-000199 | B37: CUST-0110 | C37: 45647 | D37: Candles | E37: Male | F37: Thirty | G37: Laval-qc | H37: 3 | I37: 210.48 | K37: Online | L37: 45647 | M37: Male | N37: 30 | O37: {=IF(OR(Table1[[#This Row],[Age_CLEAN]]="",Table1[[#This Row],[Age_CLEAN]]=0), "Unknown", _xlfn.IFS( Table1[[#This Row],[Age_CLEAN]]<=17,"Teen (13-17)", Table1[[#This Row],[Age_CLEAN]]<=24,"Young Adult (18-24)", Table1[[#This Row],[Age_CLEAN]]<=34,"Adult (25-34)", Table1[[#This Row],[Age_CLEAN]]<=54,"Mid-Age (35-54)", Table1[[#This Row],[Age_CLEAN]]<=75,"Older Adult (55-75)", TRUE,"Out of Range" ))} -> Adult (25-34) | P37: Laval-qc | Q37: QC | R37: 210.48
A38: TXN-2023-000688 | B38: CUST-0155 | C38: 05/11/2023 | D38: Candles | E38: Female | F38: 38 | G38: on - Vaughan | H38: 3 | I38: 124.14 | J38: 47.04 | K38: Store | L38: 45235 | M38: Female | N38: 38 | O38: {=IF(OR(Table1[[#This Row],[Age_CLEAN]]="",Table1[[#This Row],[Age_CLEAN]]=0), "Unknown", _xlfn.IFS( Table1[[#This Row],[Age_CLEAN]]<=17,"Teen (13-17)", Table1[[#This Row],[Age_CLEAN]]<=24,"Young Adult (18-24)", Table1[[#This Row],[Age_CLEAN]]<=34,"Adult (25-34)", Table1[[#This Row],[Age_CLEAN]]<=54,"Mid-Age (35-54)", Table1[[#This Row],[Age_CLEAN]]<=75,"Older Adult (55-75)", TRUE,"Out of Range" ))} -> Mid-Age (35-54) | P38: on - Vaughan | Q38: ON | R38: 124.14 | S38: 47.04
A39: TXN-2024-000585 | B39: CUST-0193 | C39: 2024.08.12 | D39: Hand Soap & Sanitizer | E39: FEMALE | F39: 26 | G39: Quebec - Longueuil | H39: 2 | I39: CAD 37.33 | J39: 8.86 | K39: Store | L39: 45516 | M39: Female | N39: 26 | O39: {=IF(OR(Table1[[#This Row],[Age_CLEAN]]="",Table1[[#This Row],[Age_CLEAN]]=0), "Unknown", _xlfn.IFS( Table1[[#This Row],[Age_CLEAN]]<=17,"Teen (13-17)", Table1[[#This Row],[Age_CLEAN]]<=24,"Young Adult (18-24)", Table1[[#This Row],[Age_CLEAN]]<=34,"Adult (25-34)", Table1[[#This Row],[Age_CLEAN]]<=54,"Mid-Age (35-54)", Table1[[#This Row],[Age_CLEAN]]<=75,"Older Adult (55-75)", TRUE,"Out of Range" ))} -> Adult (25-34) | P39: Quebec - Longueuil | Q39: QC | R39: 37.33 | S39: 8.86
A40: TXN-2024-000902 | B40: CUST-0211 | C40: 02/07/2024 | D40: Wallflower & Air Freshener | E40: F | F40: 33 | G40: London-on | H40: 1 | I40: 4.84 | J40: 2.2 | K40: Online | L40: 45475 | M40: Female | N40: 33 | O40: {=IF(OR(Table1[[#This Row],[Age_CLEAN]]="",Table1[[#This Row],[Age_CLEAN]]=0), "Unknown", _xlfn.IFS( Table1[[#This Row],[Age_CLEAN]]<=17,"Teen (13-17)", Table1[[#This Row],[Age_CLEAN]]<=24,"Young Adult (18-24)", Table1[[#This Row],[Age_CLEAN]]<=34,"Adult (25-34)", Table1[[#This Row],[Age_CLEAN]]<=54,"Mid-Age (35-54)", Table1[[#This Row],[Age_CLEAN]]<=75,"Older Adult (55-75)", TRUE,"Out of Range" ))} -> Adult (25-34) | P40: London-on | Q40: ON | R40: 4.84 | S40: 2.2
...

Sheet bbw_Pivot Table
A2: Sum of Sales_CLEAN | B2: Sum of Profit_CLEAN
A3: 35344.53 | B3: 14625.17
A5: 1. Total Sales and Profit for 2023 vs 2024
A6: Row Labels | B6: Sum of Sales_CLEAN | C6: Sum of Profit_CLEAN
A7: 2023 | B7: 18932.38 | C7: 7943.89
A8: 2024 | B8: 16412.15 | C8: 6681.28
A9: Grand Total | B9: 35344.53 | C9: 14625.17
A11: 2. Province having the highest total Sales and Profit (2023–2024 combined)
A12: Row Labels | B12: Sum of Sales_CLEAN | C12: Sum of Profit_CLEAN
A13: ON | B13: 13260.1 | C13: 5370.25
A14: QC | B14: 8563.57 | C14: 3627.5
A15: BC | B15: 4566.55 | C15: 1966.88
A16: AB | B16: 4253.22 | C16: 1708.52
A17: Grand Total | B17: 30643.44 | C17: 12673.15
A19: Row Labels | B19: Sum of Quantity
A20: 2023 | B20: 899
A21: 2024 | B21: 809
A22: Grand Total | B22: 1708
A25: 3. Category that contributes the most Sales and Profit in each year
A26: Row Labels | B26: Sum of Sales_CLEAN | C26: Sum of Profit_CLEAN
A27: Candles | B27: 11631.77 | C27: 4890.39
A28: 2023 | B28: 6777.96 | C28: 2924.55
A29: 2024 | B29: 4853.81 | C29: 1965.84
A30: Men's | B30: 8225.98 | C30: 3385.13
A31: 2023 | B31: 4332.2 | C31: 1718.35
A32: 2024 | B32: 3893.78 | C32: 1666.78
A33: Wallflower & Air Freshener | B33: 6514.96 | C33: 2568.66
A34: 2023 | B34: 3160.53 | C34: 1334.33
A35: 2024 | B35: 3354.43 | C35: 1234.33
A36: Body Care | B36: 5388.47 | C36: 2342.43
A37: 2023 | B37: 2987.25 | C37: 1309.97
A38: 2024 | B38: 2401.22 | C38: 1032.46
... A42: Grand Total | B42: 35344.53 | C42: 14625.17
A44: 4. Gender based difference in average Sales per transaction
A45: Row Labels | B45: Average of Sales_CLEAN
A46: Female | B46: 36.077535
A47: Male | B47: 36.137335
A48: Prefer not to say | B48: 34.594286
A49: Unknown | B49: 37.025868
A50: Grand Total | B50: 36.176592
...

Sheet bbw_Dashboard
K2: Yearly Sales and Profit by Category
C10: Sales by Age Group | G10: Yearly Sales by Channel
C11: Age Group | D11: Sum of Sales | E11: Sum of Profit | G11: Selling Channel | H11: Sum of Sales | I11: Sum of Profit
C12: ='bbw_Pivot Table'!A97 -> Older Adult (55-75) | D12: ='bbw_Pivot Table'!B97 -> 11751.28 | E12: ='bbw_Pivot Table'!C97 -> 4819.53 | G12: ='bbw_Pivot Table'!A107 -> 2023 | H12: ='bbw_Pivot Table'!B107 -> 18932.38 | I12: ='bbw_Pivot Table'!C107 -> 7943.89
C13: ='bbw_Pivot Table'!A98 -> Mid-Age (35-54) | D13: ='bbw_Pivot Table'!B98 -> 9138.41 | E13: ='bbw_Pivot Table'!C98 -> 3953.69 | G13: ='bbw_Pivot Table'!A108 -> Online | H13: ='bbw_Pivot Table'!B108 -> 9755.83 | I13: ='bbw_Pivot Table'!C108 -> 4233.16
C14: ='bbw_Pivot Table'!A99 -> Adult (25-34) | D14: ='bbw_Pivot Table'!B99 -> 6060.59 | E14: ='bbw_Pivot Table'!C99 -> 2237.55 | G14: ='bbw_Pivot Table'!A109 -> Store | H14: ='bbw_Pivot Table'!B109 -> 9176.55 | I14: ='bbw_Pivot Table'!C109 -> 3710.73
C15: ='bbw_Pivot Table'!A100 -> Young Adult (18-24) | D15: ='bbw_Pivot Table'!B100 -> 4038.48 | E15: ='bbw_Pivot Table'!C100 -> 1691.82 | G15: ='bbw_Pivot Table'!A110 -> 2024 | H15: ='bbw_Pivot Table'!B110 -> 16412.15 | I15: ='bbw_Pivot Table'!C110 -> 6681.28
C16: ='bbw_Pivot Table'!A101 -> Teen (13-17) | D16: ='bbw_Pivot Table'!B101 -> 3295.63 | E16: ='bbw_Pivot Table'!C101 -> 1373.92 | G16: ='bbw_Pivot Table'!A111 -> Online | H16: ='bbw_Pivot Table'!B111 -> 8461.88 | I16: ='bbw_Pivot Table'!C111 -> 3378.42
C17: ='bbw_Pivot Table'!A102 -> Unknown | D17: ='bbw_Pivot Table'!B102 -> 1060.14 | E17: ='bbw_Pivot Table'!C102 -> 548.66 | G17: ='bbw_Pivot Table'!A112 -> Store | H17: ='bbw_Pivot Table'!B112 -> 7950.27 | I17: ='bbw_Pivot Table'!C112 -> 3302.86
C18: ='bbw_Pivot Table'!A103 -> Grand Total | D18: ='bbw_Pivot Table'!B103 -> 35344.53 | E18: ='bbw_Pivot Table'!C103 -> 14625.17 | G18: ='bbw_Pivot Table'!A113 -> Grand Total | H18: ='bbw_Pivot Table'!B113 -> 35344.53 | I18: ='bbw_Pivot Table'!C113 -> 14625.17
